Workbook

Sheet Local HTA submissions
A1: Number | B1: EMEA team | C1: HTA body | D1: Subcategory | E1: Therapy area | F1: Indication | G1: Year | H1: End Year | I1: Scope of IQVIA support | J1: Outcome | K1: Product/indication | AA1: {=_xlfn.UNIQUE(B:B)} -> EMEA team | AB1: {=_xlfn.UNIQUE(C:C)} -> HTA body | AC1: {=_xlfn.UNIQUE(D:D)} -> Subcategory | AD1: {=_xlfn.UNIQUE(E:E)} -> Therapy area | AE1: {=_xlfn.UNIQUE(F:F)} -> Indication | AF1: {=_xlfn.UNIQUE(G:G)} -> Year | AG1: {=_xlfn.UNIQUE(H:H)} -> End Year | AH1: {=_xlfn.UNIQUE(I:I)} -> Scope of IQVIA support | AI1: {=_xlfn.UNIQUE(J:J)} -> Outcome | AJ1: {=_xlfn.UNIQUE(K:K)} -> Product/indication
A2: 1 | B2: England | C2: NICE | D2: NICE Technology appraisals | E2: Oncology | F2: Non metastatic castration refractory prostate cancer (potential resubmission) | G2: 2021 | H2: =G2 -> 2021 | I2: CEM adaptation, BIM, STA write-up, post-submission support | J2: Ongoing | K2: Enzalutamide | AA2: England | AB2: NICE | AC2: NICE Technology appraisals | AD2: Oncology | AE2: Non metastatic castration refractory prostate cancer (potential resubmission) | AF2: 2021 | AG2: 2021 | AH2: CEM adaptation, BIM, STA write-up, post-submission support | AI2: Ongoing | AJ2: Enzalutamide
A3: 2 | B3: England | C3: NICE | D3: NICE Technology appraisals | E3: Oncology | F3: Metastatic hormone-sensitive prostate cancer | G3: 2019 | H3: 2021 | I3: CEM validation, BIM, STA write up, strategy validation with KOLs, post submission support, SLR + updates, NMA | J3: Recommended | K3: Enzalutamide | AA3: Scotland | AB3: SMC | AC3: NHSE - Specialised commissioning | AD3: Blood and immune system | AE3: Metastatic hormone-sensitive prostate cancer | AF3: 2019 | AG3: 2020 | AH3: CEM validation, BIM, STA write up, strategy validation with KOLs, post submission support, SLR + updates, NMA | AI3: Recommended | AJ3: Roxadustat
A4: 3 | B4: England | C4: NICE | D4: NICE Technology appraisals | E4: Blood and immune system | F4: Anaemia in CKD | G4: 2021 | H4: =G4 -> 2021 | I4: CEM adaptation, BIM, STA write-up, post-submission support | J4: Ongoing | K4: Roxadustat | AA4: Wales | AB4: AWMSG | AC4: N/A | AD4: Gastroenterology | AE4: Anaemia in CKD | AF4: 2020 | AG4: 2019 | AH4: Early scientific advice, CEM, BIM, SLR, ITC, STA write-up, post-submission support | AI4: Postponed | AJ4: Filgotinib
A5: 4 | B5: England | C5: NICE | D5: NICE Technology appraisals | E5: Gastroenterology | F5: Moderate-to-severe ulcerative colitis | G5: 2021 | H5: =G5 -> 2021 | I5: CEM adaptation, BIM, STA write-up, post-submission support | J5: Ongoing | K5: Filgotinib | AA5: Ireland | AB5: NCPE | AC5: Other | AD5: Cardiovascular diseases | AE5: Moderate-to-severe ulcerative colitis | AF5: 2018 | AG5: 2018 | AH5: STA write-up, post-submission support | AI5: Withdrawn | AJ5: Cabozantinib for HCC
A6: 5 | B6: England | C6: NICE | D6: NICE Technology appraisals | E6: Oncology | F6: Oncology - solid tumour | G6: 2021 | H6: =G6 -> 2021 | I6: Early scientific advice, CEM, BIM, SLR, ITC, STA write-up, post-submission support | J6: Ongoing | K6: Cabozantinib for HCC | AA6: Germany | AB6: G-BA | AC6: AIFA Technology appraisals | AD6: Respiratory | AE6: Oncology - solid tumour | AF6: 2017 | AG6: 2017 | AH6: CEM adaptation, STA write-up | AI6: Not recommended | AJ6: Libtayo® for NSCLC
A7: 6 | B7: England | C7: NICE | D7: NICE Technology appraisals | E7: Oncology | F7: Oncology - solid tumour | G7: 2021 | H7: =G7 -> 2021 | I7: STA write-up, post-submission support | J7: Ongoing | K7: Libtayo® for NSCLC | AA7: Spain | AB7: N/A | AC7: 0 | AD7: Muscoloskeletal | AE7: Heart failure | AF7: 2016 | AG7: 2016 | AH7: CEM adaptation, BIM adaptation, Section B3 development, SLR update | AI7: Pending | AJ7: Jardiance® for HFrEF
A8: 7 | B8: England | C8: NICE | D8: NICE Technology appraisals | E8: Cardiovascular diseases | F8: Heart failure | G8: 2021 | H8: =G8 -> 2021 | I8: CEM adaptation, STA write-up | J8: Ongoing | K8: Jardiance® for HFrEF | AA8: Italy | AB8: AIFA | AD8: Other/None | AE8: Cystic fibrosis | AF8: 2015 | AG8: 2015 | AH8: CEM, BIM, STA write up | AI8: Full assessment requested | AJ8: ELX/TEZ/IVA
A9: 8 | B9: England | C9: NICE | D9: NICE Technology appraisals | E9: Respiratory | F9: Cystic fibrosis | G9: 2020 | H9: =G9 -> 2020 | I9: CEM adaptation, BIM adaptation, Section B3 development, SLR update | J9: Postponed | K9: ELX/TEZ/IVA | AA9: France | AB9: CEESP | AD9: Metabolic/Endocrine Disorders | AE9: Moderate-to-severe rheumatoid arthritis | AF9: 2014 | AG9: 2014 | AH9: CEM, BIM, STA write up | AI9: Recommended (x2) | AJ9: 0
A10: 9 | B10: England | C10: NICE | D10: NICE Technology appraisals | E10: Muscoloskeletal | F10: Moderate-to-severe rheumatoid arthritis | G10: 2020 | H10: =G10 -> 2020 | I10: CEM adaptation, BIM, STA write-up, post-submission support | J10: Recommended | K10: Filgotinib | AA10: Portugal | AB10: CT | AD10: Dermatology | AE10: Genetic disease | AF10: 2013 | AG10: 2013 | AH10: CEM validation, BIM, STA write up, post submission support | AI10: Delayed | AJ10: Upadacitinib (recommended for severe RA)
A11: 10 | B11: England | C11: NICE | D11: NICE Technology appraisals | E11: Other/None | F11: Genetic disease | G11: 2020 | H11: =G11 -> 2020 | I11: CEM, BIM, STA write up | J11: Ongoing | AA11: Greece | AB11: INFARMED | AD11: Infectious diseases | AE11: Oncology - haemato-oncology | AF11: 2012 | AG11: 2012 | AH11: CEM, BIM, STA write-up | AI11: Procedure completed - resubmitted | AJ11: Larotrectinib (VItrakvi®)for NTRK fusion
A12: 11 | B12: England | C12: NICE | D12: NICE Technology appraisals | E12: Oncology | F12: Oncology - haemato-oncology | G12: 2020 | H12: =G12 -> 2020 | I12: CEM, BIM, STA write up | J12: Ongoing | AA12: Netherlands | AB12: Greek HTA Committee | AD12: Ophthalmology | AE12: Cardiovascular disease | AF12: 0 | AG12: 0 | AH12: CEM adaptation, STA write-up, post-submission support | AI12: Procedure completed - significant additional benefit | AJ12: Liraglutide for obesity
A13: 12 | B13: England | C13: NICE | D13: NICE Technology appraisals | E13: Cardiovascular diseases | F13: Cardiovascular disease | G13: 2020 | H13: =G13 -> 2020 | I13: CEM validation, BIM, STA write up, post submission support | J13: Ongoing | AA13: Czech Republic | AB13: Zorginstituut Nederland | AD13: Gynacology | AE13: Oncology – haemato-oncology | AG13: Ongoing | AH13: CEM, BIM, STA write-up | AI13: Procedure completed - indication of a low additional benefit | AJ13: Liposomal cytarabine–daunorubicin for untreated acute myeloid leukaemia
A14: 13 | B14: England | C14: NICE | D14: NICE Technology appraisals | E14: Oncology | F14: Oncology - haemato-oncology | G14: 2019 | H14: =G14 -> 2019 | I14: CEM, BIM, STA write-up | J14: Withdrawn | AA14: Slovakia | AB14: Zorgverzekeraars Nederland | AD14: Digestive system | AE14: Oncology – solid tumour | AH14: CEM, BIM, STA write-up, post-submission support | AI14: Not submitted | AJ14: Baricitinib (recommended for severe RA)
A15: 14 | B15: England | C15: NICE | D15: NICE Technology appraisals | E15: Muscoloskeletal | F15: Moderate-to-severe rheumatoid arthritis | G15: 2019 | H15: =G15 -> 2019 | I15: CEM adaptation, STA write-up, post-submission support | J15: Recommended | K15: Upadacitinib (recommended for severe RA) | AA15: 0 | AB15: SUKL | AD15: Central nervous system | AE15: Type 1 diabetes | AH15: CEM, BIM, post submission support | AI15: 0 | AJ15: Iluvien
A16: 15 | B16: England | C16: NICE | D16: NICE Technology appraisals | E16: Oncology | F16: Oncology – haemato-oncology | G16: 2019 | H16: =G16 -> 2019 | I16: CEM, BIM, STA write-up | J16: Ongoing | AB16: ŠUKL | AD16: Mental and behavioural disorders | AE16: Electrolyte imbalance | AH16: SLR, adaptation of CEM and BIM, STA write up | AI16: Procedure completed - no additional benefit | AJ16: Bronchitol
A17: 16 | B17: England | C17: NICE | D17: NICE Technology appraisals | E17: Oncology | F17: Oncology – solid tumour | G17: 2019 | H17: =G17 -> 2019 | I17: CEM, BIM, STA write-up, post-submission support | J17: Recommended | K17: Larotrectinib (VItrakvi®)for NTRK fusion | AB17: 0 | AD17: Rare Disease | AE17: Metabolic disease | AH17: CEM adaptation, STA write up, post-submission support | AI17: Procedure completed - evidence of substantial additional benefit. | AJ17: Larotrectinib (Vitrakvi®) for NTRK fusion cancer
A18: 17 | B18: England | C18: NICE | D18: NICE Technology appraisals | E18: Oncology | F18: Oncology – solid tumour | G18: 2019 | H18: =G18 -> 2019 | I18: CEM, BIM, STA write-up | J18: Recommended | AD18: Vaccines | AE18: Acute myeloid leukaemia | AH18: FTA write up, post-submission support | AI18: Procedure completed - Orphan - additional benefit | AJ18: Leuprorelin acetate (Prostap®) for pre- and perimenopausal women with advanced breast cancer suitable for hormonal manipulation.
A19: 18 | B19: England | C19: NICE | D19: NICE Technology appraisals | E19: Metabolic/Endocrine Disorders | F19: Type 1 diabetes | G19: 2019 | H19: =G19 -> 2019 | I19: CEM, BIM, post submission support | J19: Recommended | AD19: Urology | AE19: Moderate-to-severe plaque psoriasis | AH19: CEM, BIM, STA write up, strategy validation with KOLs, post submission support, SLR + updates, NMA | AI19: Procedure completed - non-quantifiable additional benefit | AJ19: Miconazole
A20: 19 | B20: England | C20: NICE | D20: NICE Technology appraisals | E20: Cardiovascular diseases | F20: Electrolyte imbalance | G20: 2019 | H20: =G20 -> 2019 | I20: SLR, adaptation of CEM and BIM, STA write up | J20: Recommended | AD20: Neurology | AE20: Prostate cancer (high-risk nmCRPC) | AH20: SLRs, CEM, BIM, STA write up, post-submission support | AI20: Procedure completed - indication of significant additional benefit | AJ20: Dalbavancin
A21: 20 | B21: England | C21: NICE | D21: NICE Technology appraisals | E21: Oncology | F21: Oncology – solid tumour | G21: 2019 | H21: =G21 -> 2019 | I21: CEM, BIM, STA write-up | J21: Not recommended | AD21: Rheumatology | AE21: Hepatitis C | AH21: CEM, BIM, post-submission support | AI21: Completed | AJ21: Fidaxomicin
A22: 21 | B22: England | C22: NICE | D22: NICE Technology appraisals | E22: Metabolic/Endocrine Disorders | F22: Metabolic disease | G22: 2019 | H22: =G22 -> 2019 | I22: CEM adaptation, STA write up, post-submission support | J22: Recommended | K22: Liraglutide for obesity | AD22: Cardiology | AE22: Autologous chrondrocyte implantation | AH22: CEM/BIM revision, updated submission under CDF framework | AI22: Procedure completed - Indication of significant additional benefit | AJ22: Xtandi
A23: 22 | B23: England | C23: NICE | D23: NICE Technology appraisals | E23: Oncology | F23: Acute myeloid leukaemia | G23: 2018 | H23: =G23 -> 2018 | I23: CEM adaptation, STA write up, post-submission support | J23: Recommended | K23: Liposomal cytarabine–daunorubicin for untreated acute myeloid leukaemia | AD23: Rare disease/ Ophthalmology | AE23: 3rd Line Metastatic/Unresectable Gastrointestinal Stromal Tumour | AH23: SLR, CEM, BIM, STA write up | AI23: X | AJ23: Risankizumab
A24: 23 | B24: England | C24: NICE | D24: NICE Technology appraisals | E24: Dermatology | F24: Moderate-to-severe plaque psoriasis | G24: 2018 | H24: =G24 -> 2018 | I24: FTA write up, post-submission support | J24: Ongoing | AD24: Rare disease/ Rheumatology | AE24: Metastatic hepatocellular carcinoma | AH24: Economic/QoL SLR, CEM, BIM, STA write up | AI24: Class C | AJ24: Evolocumab
A25: 24 | B25: England | C25: NICE | D25: NICE Technology appraisals | E25: Oncology | F25: Acute myeloid leukaemia | G25: 2018 | H25: =G25 -> 2018 | I25: CEM, BIM, STA write up | J25: Ongoing | AD25: Dermatology/ Rheumatology | AE25: Visual impairment due to macular oedema secondary to branch retinal vein occlusion | AH25: Updated survival data analysis, adaptation of CEM, BIM, STA write up | AI25: Reimbursed | AJ25: Blinatumomab
A26: 25 | B26: England | C26: NICE | D26: NICE Technology appraisals | E26: Oncology | F26: Prostate cancer (high-risk nmCRPC) | G26: 2018 | H26: =G26 -> 2018 | I26: CEM, BIM, STA write up, strategy validation with KOLs, post submission support, SLR + updates, NMA | J26: Not recommended | K26: Enzalutamide | AD26: Hematology | AE26: Advanced hepatocellular carcinoma | AH26: SLR, CEM, BIM, STA write up, represented company at NICE | AI26: Re-negotiated | AJ26: Apixaban
A27: 26 | B27: England | C27: NICE | D27: NICE Technology appraisals | E27: Infectious diseases | F27: Hepatitis C | G27: 2017 | H27: =G27 -> 2017 | I27: CEM adaptation, STA write up, post-submission support | J27: Recommended | AD27: Medical device | AE27: Prostate cancer | AH27: CEM, MTA write up | AI27: Reimbursed & Innovative | AJ27: Anamorelin
A28: 27 | B28: England | C28: NICE | D28: NICE Technology appraisals | E28: Muscoloskeletal | F28: Autologous chrondrocyte implantation | G28: 2017 | H28: =G28 -> 2017 | I28: SLRs, CEM, BIM, STA write up, post-submission support | J28: Recommended | AD28: Surgical operation | AE28: Treatment of adults with castration-resistant prostate cancer, symptomatic bone metastases and no known visceral metastases. | AH28: CEM | AI28: EMA withdrawn | AJ28: Anamorelin
A29: 28 | B29: England | C29: NICE | D29: NICE Technology appraisals | E29: Oncology | F29: 3rd Line Metastatic/Unresectable Gastrointestinal Stromal Tumour | G29: 2017 | H29: =G29 -> 2017 | I29: CEM, BIM, STA write up | J29: Recommended | AD29: Psychiatry | AE29: Dupuytren's contracture | AH29: NMA, CEM, STA write up | AI29: Under AIFA evaluation | AJ29: Perampanel
A30: 29 | B30: England | C30: NICE | D30: NICE Technology appraisals | E30: Muscoloskeletal | F30: Moderate-to-severe rheumatoid arthritis | G30: 2017 | H30: =G30 -> 2017 | I30: CEM, BIM, post-submission support | J30: Recommended | K30: Baricitinib (recommended for severe RA) | AD30: Haemato-oncology | AE30: Type 2 diabetes | AH30: CEM, BIM, STA write up, strategy validation with KOLs, post submission support, OS adjustment | AI30: Completed (reimbursed) | AJ30: Empagliflozin/Metformin
A31: 30 | B31: England | C31: NICE | D31: NICE Technology appraisals | E31: Oncology | F31: Metastatic hepatocellular carcinoma | G31: 2016 | H31: =G31 -> 2016 | I31: CEM/BIM revision, updated submission under CDF framework | J31: Pending | AD31: 0 | AE31: Visual impairment due to diabetic macular oedema | AH31: CEM, BIM, STA write up, post submission support | AI31: Completed (under evaluation) | AJ31: Empagliflozin/Linagliptin
A32: 31 | B32: England | C32: NICE | D32: NICE Technology appraisals | E32: Ophthalmology | F32: Visual impairment due to macular oedema secondary to branch retinal vein occlusion | G32: 2016 | H32: =G32 -> 2016 | I32: SLR, CEM, BIM, STA write up | J32: Recommended | AE32: Visual impairment caused by macular oedema secondary to central retinal vein occlusion | AH32: CEM, BIM, STA write up, strategy validation with KOLs, post submission support, SLR, NMA | AI32: Completed (HTA positive assessment) | AJ32: Empagliflozin
A33: 32 | B33: England | C33: NICE | D33: NICE Technology appraisals | E33: Oncology | F33: Advanced hepatocellular carcinoma | G33: 2016 | H33: =G33 -> 2016 | I33: CEM, BIM, STA write up | J33: Recommended | AE33: Prostate cancer (chemo-naive mCRPC) | AH33: CSP dossier | AI33: Completed (succesful negotiation) | AJ33: Plitidepsin
A34: 33 | B34: England | C34: NICE | D34: NICE Technology appraisals | E34: Dermatology | F34: Moderate-to-severe plaque psoriasis | G34: 2015 | H34: =G34 -> 2015 | I34: Economic/QoL SLR, CEM, BIM, STA write up | J34: Recommended | AE34: Rivaroxaban for the treatment of deep vein thrombosis and prevention of recurrent deep vein thrombosis and pulmonary embolism | AH34: CEM adaptation, BIM, NPAF write up, NPAF strategy validation, post submission support | AI34: Completed (not submitted yet) | AJ34: Eribulin
A35: 34 | B35: England | C35: NICE | D35: NICE Technology appraisals | E35: Oncology | F35: Prostate cancer | G35: 2015 | H35: =G35 -> 2015 | I35: Updated survival data analysis, adaptation of CEM, BIM, STA write up | J35: Recommended | AE35: Wet age-related macular degeneration | AH35: SMC submission | AI35: Positive reimbursement advice | AJ35: Blinatumomab
A36: 35 | B36: England | C36: NICE | D36: NICE Technology appraisals | E36: Oncology | F36: Treatment of adults with castration-resistant prostate cancer, symptomatic bone metastases and no known visceral metastases. | G36: 2015 | H36: =G36 -> 2015 | I36: SLR, CEM, BIM, STA write up, represented company at NICE | J36: Recommended | AE36: Diabetic macular edema | AH36: CEM adaptation, NPAF write-up, post-subimssion support | AI36: XXX | AJ36: Velmanase alfa
A37: 36 | B37: England | C37: NICE | D37: NICE Technology appraisals | E37: Muscoloskeletal | F37: Dupuytren's contracture | G37: 2015 | H37: =G37 -> 2015 | I37: CEM, MTA write up | J37: Recommended | AE37: Prostate cancer (post-chemo mCRPC) | AH37: CEM development, SLR, NPAF write-up | AI37: Reimbursed after price negotiation | AJ37: Lenvatinib
A38: 37 | B38: England | C38: NICE | D38: NICE Technology appraisals | E38: Metabolic/Endocrine Disorders | F38: Type 2 diabetes | G38: 2015 | H38: =G38 -> 2015 | I38: CEM | J38: Recommended | AE38: Rivaroxaban for treating pulmonary embolism and preventing recurrent venous thromboembolism | AH38: CEM QC, SMC submission | AI38: Price negotiation recommended | AJ38: Guselkumab
A39: 38 | B39: England | C39: NICE | D39: NICE Technology appraisals | E39: Ophthalmology | F39: Visual impairment due to diabetic macular oedema | G39: 2014 | H39: =G39 -> 2014 | I39: NMA, CEM, STA write up | J39: Recommended | AE39: Rivaroxaban for the prevention of stroke and systemic embolism in people with atrial fibrillation | AH39: SLR, model updated, SMC submission | AJ39: Sirukumab
A40: 39 | B40: England | C40: NICE | D40: NICE Technology appraisals | E40: Ophthalmology | F40: Visual impairment caused by macular oedema secondary to central retinal vein occlusion | G40: 2014 | H40: =G40 -> 2014 | I40: SLR, CEM, BIM, STA write up | J40: Recommended | AE40: In combination with oral anti-diabetic therapy for the treatment of type 2 diabetes | AH40: SMC submission and post-admission support | AJ40: Brodalumab
...

Sheet HTA scientific advice
A1: HTA body | B1: Regulatory body, if included | C1: Therapy area | D1: Indication | E1: Year | F1: Product | J1: {=_xlfn.UNIQUE(A:A)} -> HTA body | K1: {=_xlfn.UNIQUE(B:B)} -> Regulatory body, if included | L1: {=_xlfn.UNIQUE(C:C)} -> Therapy area | M1: {=_xlfn.UNIQUE(D:D)} -> Indication | N1: {=_xlfn.UNIQUE(E:E)} -> Year | O1: {=_xlfn.UNIQUE(F:F)} -> Product
A2: CADTH | B2: N/A | C2: Dermatology | D2: Atopic dermatitis | E2: 2018 | F2: nemolizumab | J2: CADTH | K2: N/A | L2: Dermatology | M2: Atopic dermatitis | N2: 2018 | O2: nemolizumab
A3: G-BA | B3: N/A | C3: Dermatology | D3: Atopic dermatitis | E3: 2018 | F3: nemolizumab | J3: G-BA | K3: EMA’s adaptive pathway process | L3: Haemato-oncology | M3: Atopic dermatitis | N3: 2021 | O3: Elrinatamab
A4: HAS | B4: N/A | C4: Dermatology | D4: Atopic dermatitis | E4: 2018 | F4: nemolizumab | J4: HAS | K4: 0 | L4: Nephrology | M4: Multiple Myeloma | N4: 2020 | O4: Axicabtagene ciloleucel (Yescarta®)
A5: NICE | B5: N/A | C5: Dermatology | D5: Atopic dermatitis | E5: 2018 | F5: nemolizumab | J5: NICE | L5: Oncology | M5: Relapsed or refractory diffuse large B cell lymphoma (DLBCL) and primary mediastinal large B cell lymphoma (PMBCL), after two or more lines of systemic therapy | N5: 2017 | O5: VIS649
A6: G-BA | B6: N/A | C6: Haemato-oncology | D6: Multiple Myeloma | E6: 2021 | F6: Elrinatamab | J6: ZIN | L6: Various | M6: Primary IgA Nephropathy | N6: 2019 | O6: IMAB362 as add on to mFOLFOX6 in 1L of CLDN18.2 positive
A7: HAS | B7: N/A | C7: Haemato-oncology | D7: Multiple Myeloma | E7: 2021 | F7: Elrinatamab | J7: EUnetHTA | L7: 0 | M7: HER2 negative metastatic gastric and gastroesophageal junction adenocarcinoma | N7: 2016 | O7: MEN1116
A8: NICE | B8: N/A | C8: Haemato-oncology | D8: Multiple Myeloma | E8: 2021 | F8: Elrinatamab | J8: Parallel EMA / HTA | M8: Breast Cancer | N8: 0 | O8: Enfortumab vedotin
A9: ZIN | B9: N/A | C9: Haemato-oncology | D9: Relapsed or refractory diffuse large B cell lymphoma (DLBCL) and primary mediastinal large B cell lymphoma (PMBCL), after two or more lines of systemic therapy | E9: 2020 | F9: Axicabtagene ciloleucel (Yescarta®) | J9: 0 | M9: First-line treatment of locally advanced or metastatic urothelial carcinoma | O9: PLacental eXpanded (PLX) cells
A10: HAS | B10: N/A | C10: Nephrology | D10: Primary IgA Nephropathy | E10: 2021 | F10: VIS649 | M10: Somatic cell therapy | O10: 0
A11: EUnetHTA | B11: N/A | C11: Oncology | D11: HER2 negative metastatic gastric and gastroesophageal junction adenocarcinoma | E11: 2017 | F11: IMAB362 as add on to mFOLFOX6 in 1L of CLDN18.2 positive | M11: 0 | O11: Elrinatanab
A12: G-BA | B12: N/A | C12: Oncology | D12: Breast Cancer | E12: 2021 | F12: MEN1116
A13: NICE | B13: N/A | C13: Oncology | D13: Breast Cancer | E13: 2021 | F13: MEN1116
A14: NICE | B14: N/A | C14: Oncology | D14: First-line treatment of locally advanced or metastatic urothelial carcinoma | E14: 2019 | F14: Enfortumab vedotin
A15: Parallel EMA / HTA | B15: EMA’s adaptive pathway process | C15: Various | D15: Somatic cell therapy | E15: 2016 | F15: PLacental eXpanded (PLX) cells
A542: NICE | C542: Oncology | D542: Multiple Myeloma | E542: 2021 | F542: Elrinatanab
A543: NICE | C543: Oncology | D543: Breast cancer | E543: 2021 | F543: MEN1116
A544: HAS | C544: Oncology | D544: Breast cancer | E544: 2021 | F544: MEN1116

Sheet GVDs
A1: Therapy area | B1: Indication | C1: Year | D1: Product | J1: {=_xlfn.UNIQUE(A:A)} -> Therapy area | K1: {=_xlfn.UNIQUE(B:B)} -> Indication | L1: {=_xlfn.UNIQUE(C:C)} -> Year | M1: {=_xlfn.UNIQUE(D:D)} -> Product
A2: Haematology | B2: Anticoagulant product in venous thromboembolism | C2: 2015 | J2: Haematology | K2: Anticoagulant product in venous thromboembolism | L2: 2015 | M2: 0
A3: Haemato-oncology | B3: Mantle Cell Lymphoma product | C3: 2015 | J3: Haemato-oncology | K3: Mantle Cell Lymphoma product | L3: 2016 | M3: Binimetinib + encorafenib
A4: Metabolic/Endocrine Disorders | B4: Acromegaly product | C4: 2015 | J4: Metabolic/Endocrine Disorders | K4: Acromegaly product | L4: 2017 | M4: Veyvondi
A5: Cardiorenal/Metabolic | B5: Hyperkalemia product | C5: 2016 | J5: Cardiorenal/Metabolic | K5: Hyperkalemia product | L5: 2018 | M5: nAB
A6: Metabolic/Endocrine Disorders | B6: DPP-4 / SGLT-2 combination product in T2DM (update) | C6: 2016 | J6: Oncology | K6: DPP-4 / SGLT-2 combination product in T2DM (update) | L6: 2019 | M6: Opdivo + Cabozantinib
A7: Oncology | B7: Melanoma | C7: 2017 | D7: Binimetinib + encorafenib | J7: Respiratory | K7: Melanoma | L7: 2020
A8: Oncology | B8: Metastatic colorectal cancer product | C8: 2017 | J8: Central nervous system | K8: Metastatic colorectal cancer product | L8: 2021
A9: Respiratory | B9: Asthma product | C9: 2017 | J9: Infectious diseases | K9: Asthma product | L9: 0
A10: Respiratory | B10: Chronic Obstructive Pulmonary Disease product | C10: 2017 | J10: Mental illness | K10: Chronic Obstructive Pulmonary Disease product
A11: Central nervous system | B11: Diabetic peripheral neuropathy/post-herpetic neuralgia product | C11: 2018 | J11: 0 | K11: Diabetic peripheral neuropathy/post-herpetic neuralgia product
A12: Infectious diseases | B12: Pseudomonas aeruginosa anti-infective product | C12: 2018 | K12: Pseudomonas aeruginosa anti-infective product
A13: Mental illness | B13: Digital treatment program for depression | C13: 2018 | K13: Digital treatment program for depression
A14: Metabolic/Endocrine Disorders | B14: GLP-1 agonist product in T2DM | C14: 2018 | K14: GLP-1 agonist product in T2DM
A15: Oncology | B15: Cutaneous melanoma product | C15: 2018 | K15: Cutaneous melanoma product
A16: Oncology | B16: Non-small cell lung cancer IO product | C16: 2018 | K16: Non-small cell lung cancer IO product
A17: Central nervous system | B17: Epilepsy product (update) | C17: 2019 | K17: Epilepsy product (update)
A18: Infectious diseases | B18: HIV product | C18: 2019 | K18: HIV product
A19: Oncology | B19: Hepatocellular cell carcinoma/renal cell carcinoma product | C19: 2019 | K19: Hepatocellular cell carcinoma/renal cell carcinoma product
A20: Haemato-oncology | B20: Non Hodgkin Lymphoma | C20: 2020 | K20: Non Hodgkin Lymphoma
A21: Haemato-oncology | B21: Relapsed/refractory AML product | C21: 2020 | K21: Relapsed/refractory AML product
A22: Oncology | B22: Unresectable malignant pleural mesothelioma | C22: 2020 | K22: Unresectable malignant pleural mesothelioma
A23: Haematology | B23: von Willebrand disease (an inherited bleeding disorder) | C23: 2021 | D23: Veyvondi | K23: von Willebrand disease (an inherited bleeding disorder)
A24: Infectious diseases | B24: COVID-19 infection | C24: 2021 | D24: nAB | K24: COVID-19 infection
A25: Oncology | B25: Advanced renal cell carcinoma | C25: 2021 | D25: Opdivo + Cabozantinib | K25: Advanced renal cell carcinoma
K26: 0

Sheet Local HTA Pivot Table
A2: Count of HTA body | B2: Column Labels
A3: Row Labels | B3: AIFA | C3: AWMSG | D3: G-BA | E3: Greek HTA Committee | F3: INFARMED | G3: N/A | H3: NCPE | I3: NICE | J3: SMC | K3: SUKL | L3: ŠUKL | M3: Zorginstituut Nederland | N3: Zorgverzekeraars Nederland | O3: Grand Total
A4: 2012 | I4: 4 | J4: 2 | O4: 6
A5: 2013 | C5: 1 | H5: 3 | I5: 5 | J5: 1 | O5: 10
A6: 2014 | H6: 2 | I6: 3 | O6: 5
A7: 2015 | C7: 1 | D7: 7 | G7: 5 | H7: 2 | I7: 5 | J7: 9 | O7: 29
A8: 2016 | C8: 1 | D8: 9 | G8: 8 | H8: 2 | I8: 3 | J8: 1 | O8: 24
A9: 2017 | D9: 11 | G9: 6 | H9: 2 | I9: 5 | J9: 1 | O9: 25
A10: 2018 | B10: 6 | C10: 2 | D10: 12 | E10: 3 | G10: 7 | H10: 2 | I10: 4 | J10: 2 | K10: 1 | L10: 1 | M10: 1 | O10: 41
A11: 2019 | B11: 6 | C11: 1 | D11: 14 | E11: 6 | F11: 1 | G11: 7 | H11: 3 | I11: 10 | J11: 3 | M11: 4 | N11: 1 | O11: 56
A12: 2020 | B12: 17 | D12: 25 | E12: 9 | F12: 2 | G12: 5 | H12: 2 | I12: 5 | J12: 3 | M12: 3 | N12: 1 | O12: 72
A13: 2021 | B13: 17 | D13: 7 | E13: 2 | F13: 3 | G13: 2 | H13: 4 | I13: 6 | J13: 5 | M13: 5 | O13: 51
A14: Grand Total | B14: 46 | C14: 6 | D14: 85 | E14: 20 | F14: 6 | G14: 40 | H14: 22 | I14: 50 | J14: 27 | K14: 1 | L14: 1 | M14: 13 | N14: 2 | O14: 319

Sheet HTA scientific advice Pivot
A2: Count of Year | B2: Column Labels
A3: Row Labels | B3: 2016 | C3: 2017 | D3: 2018 | E3: 2019 | F3: 2020 | G3: 2021 | H3: Grand Total
A4: Dermatology | D4: 4 | H4: 4
A5: Haemato-oncology | F5: 1 | G5: 3 | H5: 4
A6: Nephrology | G6: 1 | H6: 1
A7: Oncology | C7: 1 | E7: 1 | G7: 2 | H7: 4
A8: Misc | B8: 1 | H8: 1
A9: Grand Total | B9: 1 | C9: 1 | D9: 4 | E9: 1 | F9: 1 | G9: 6 | H9: 14

Sheet GVDs Pivot Table
A3: Count of Indication | B3: Column Labels
A4: Row Labels | B4: 2015 | C4: 2016 | D4: 2017 | E4: 2018 | F4: 2019 | G4: 2020 | H4: 2021 | I4: Grand Total
A5: Acromegaly product | B5: 1 | I5: 1
A6: Advanced renal cell carcinoma | H6: 1 | I6: 1
A7: Anticoagulant product in venous thromboembolism | B7: 1 | I7: 1
A8: Asthma product | D8: 1 | I8: 1
A9: Chronic Obstructive Pulmonary Disease product | D9: 1 | I9: 1
A10: COVID-19 infection | H10: 1 | I10: 1
A11: Cutaneous melanoma product | E11: 1 | I11: 1
A12: Diabetic peripheral neuropathy/post-herpetic neuralgia product | E12: 1 | I12: 1
A13: Digital treatment program for depression | E13: 1 | I13: 1
A14: DPP-4 / SGLT-2 combination product in T2DM (update) | C14: 1 | I14: 1
A15: Epilepsy product (update) | F15: 1 | I15: 1
A16: GLP-1 agonist product in T2DM | E16: 1 | I16: 1
A17: Hepatocellular cell carcinoma/renal cell carcinoma product | F17: 1 | I17: 1
A18: HIV product | F18: 1 | I18: 1
A19: Hyperkalemia product | C19: 1 | I19: 1
A20: Mantle Cell Lymphoma product | B20: 1 | I20: 1
A21: Melanoma | D21: 1 | I21: 1
A22: Metastatic colorectal cancer product | D22: 1 | I22: 1
A23: Non Hodgkin Lymphoma | G23: 1 | I23: 1
A24: Non-small cell lung cancer IO product | E24: 1 | I24: 1
A25: Pseudomonas aeruginosa anti-infective product | E25: 1 | I25: 1
A26: Relapsed/refractory AML product | G26: 1 | I26: 1
A27: Unresectable malignant pleural mesothelioma | G27: 1 | I27: 1
A28: von Willebrand disease (an inherited bleeding disorder) | H28: 1 | I28: 1
A29: Grand Total | B29: 3 | C29: 2 | D29: 4 | E29: 6 | F29: 3 | G29: 3 | H29: 3 | I29: 24

Sheet By year
A3: Local HTA submissions
A4: HTA submissions by Year & HTA body
A5: Year | B5: NICE | C5: SMC | D5: AWMSG | E5: NCPE | F5: G-BA | G5: AIFA | H5: AEMPS | I5: CEESP | J5: CT | K5: Total
A6: ='Local HTA submissions'!AG12 -> 0 | B6: =COUNTIFS('Local HTA submissions'!$H:$H,'By year'!$A6,'Local HTA submissions'!$C:$C,'By year'!B$5) -> 0 | C6: =COUNTIFS('Local HTA submissions'!$H:$H,'By year'!$A6,'Local HTA submissions'!$C:$C,'By year'!C$5) -> 0 | D6: =COUNTIFS('Local HTA submissions'!$H:$H,'By year'!$A6,'Local HTA submissions'!$C:$C,'By year'!D$5) -> 0 | E6: =COUNTIFS('Local HTA submissions'!$H:$H,'By year'!$A6,'Local HTA submissions'!$C:$C,'By year'!E$5) -> 0 | F6: =COUNTIFS('Local HTA submissions'!$H:$H,'By year'!$A6,'Local HTA submissions'!$C:$C,'By year'!F$5) -> 0 | G6: =COUNTIFS('Local HTA submissions'!$H:$H,'By year'!$A6,'Local HTA submissions'!$C:$C,'By year'!G$5) -> 0 | H6: =COUNTIFS('Local HTA submissions'!$H:$H,'By year'!$A6,'Local HTA submissions'!$C:$C,'By year'!H$5) -> 0 | I6: =COUNTIFS('Local HTA submissions'!$H:$H,'By year'!$A6,'Local HTA submissions'!$C:$C,'By year'!I$5) -> 0 | J6: =COUNTIFS('Local HTA submissions'!$H:$H,'By year'!$A6,'Local HTA submissions'!$C:$C,'By year'!J$5) -> 0 | K6: =SUM(B6:J6) -> 0
A7: ='Local HTA submissions'!AG11 -> 2012 | B7: =COUNTIFS('Local HTA submissions'!$H:$H,'By year'!$A7,'Local HTA submissions'!$C:$C,'By year'!B$5) -> 4 | C7: =COUNTIFS('Local HTA submissions'!$H:$H,'By year'!$A7,'Local HTA submissions'!$C:$C,'By year'!C$5) -> 2 | D7: =COUNTIFS('Local HTA submissions'!$H:$H,'By year'!$A7,'Local HTA submissions'!$C:$C,'By year'!D$5) -> 0 | E7: =COUNTIFS('Local HTA submissions'!$H:$H,'By year'!$A7,'Local HTA submissions'!$C:$C,'By year'!E$5) -> 0 | F7: =COUNTIFS('Local HTA submissions'!$H:$H,'By year'!$A7,'Local HTA submissions'!$C:$C,'By year'!F$5) -> 0 | G7: =COUNTIFS('Local HTA submissions'!$H:$H,'By year'!$A7,'Local HTA submissions'!$C:$C,'By year'!G$5) -> 0 | H7: =COUNTIFS('Local HTA submissions'!$H:$H,'By year'!$A7,'Local HTA submissions'!$C:$C,'By year'!H$5) -> 0 | I7: =COUNTIFS('Local HTA submissions'!$H:$H,'By year'!$A7,'Local HTA submissions'!$C:$C,'By year'!I$5) -> 0 | J7: =COUNTIFS('Local HTA submissions'!$H:$H,'By year'!$A7,'Local HTA submissions'!$C:$C,'By year'!J$5) -> 0 | K7: =SUM(B7:J7) -> 6
A8: ='Local HTA submissions'!AG10 -> 2013 | B8: =COUNTIFS('Local HTA submissions'!$H:$H,'By year'!$A8,'Local HTA submissions'!$C:$C,'By year'!B$5) -> 5 | C8: =COUNTIFS('Local HTA submissions'!$H:$H,'By year'!$A8,'Local HTA submissions'!$C:$C,'By year'!C$5) -> 1 | D8: =COUNTIFS('Local HTA submissions'!$H:$H,'By year'!$A8,'Local HTA submissions'!$C:$C,'By year'!D$5) -> 1 | E8: =COUNTIFS('Local HTA submissions'!$H:$H,'By year'!$A8,'Local HTA submissions'!$C:$C,'By year'!E$5) -> 3 | F8: =COUNTIFS('Local HTA submissions'!$H:$H,'By year'!$A8,'Local HTA submissions'!$C:$C,'By year'!F$5) -> 0 | G8: =COUNTIFS('Local HTA submissions'!$H:$H,'By year'!$A8,'Local HTA submissions'!$C:$C,'By year'!G$5) -> 0 | H8: =COUNTIFS('Local HTA submissions'!$H:$H,'By year'!$A8,'Local HTA submissions'!$C:$C,'By year'!H$5) -> 0 | I8: =COUNTIFS('Local HTA submissions'!$H:$H,'By year'!$A8,'Local HTA submissions'!$C:$C,'By year'!I$5) -> 0 | J8: =COUNTIFS('Local HTA submissions'!$H:$H,'By year'!$A8,'Local HTA submissions'!$C:$C,'By year'!J$5) -> 0 | K8: =SUM(B8:J8) -> 10
A9: ='Local HTA submissions'!AG9 -> 2014 | B9: =COUNTIFS('Local HTA submissions'!$H:$H,'By year'!$A9,'Local HTA submissions'!$C:$C,'By year'!B$5) -> 3 | C9: =COUNTIFS('Local HTA submissions'!$H:$H,'By year'!$A9,'Local HTA submissions'!$C:$C,'By year'!C$5) -> 0 | D9: =COUNTIFS('Local HTA submissions'!$H:$H,'By year'!$A9,'Local HTA submissions'!$C:$C,'By year'!D$5) -> 0 | E9: =COUNTIFS('Local HTA submissions'!$H:$H,'By year'!$A9,'Local HTA submissions'!$C:$C,'By year'!E$5) -> 2 | F9: =COUNTIFS('Local HTA submissions'!$H:$H,'By year'!$A9,'Local HTA submissions'!$C:$C,'By year'!F$5) -> 0 | G9: =COUNTIFS('Local HTA submissions'!$H:$H,'By year'!$A9,'Local HTA submissions'!$C:$C,'By year'!G$5) -> 0 | H9: =COUNTIFS('Local HTA submissions'!$H:$H,'By year'!$A9,'Local HTA submissions'!$C:$C,'By year'!H$5) -> 0 | I9: =COUNTIFS('Local HTA submissions'!$H:$H,'By year'!$A9,'Local HTA submissions'!$C:$C,'By year'!I$5) -> 0 | J9: =COUNTIFS('Local HTA submissions'!$H:$H,'By year'!$A9,'Local HTA submissions'!$C:$C,'By year'!J$5) -> 0 | K9: =SUM(B9:J9) -> 5
A10: ='Local HTA submissions'!AG8 -> 2015 | B10: =COUNTIFS('Local HTA submissions'!$H:$H,'By year'!$A10,'Local HTA submissions'!$C:$C,'By year'!B$5) -> 5 | C10: =COUNTIFS('Local HTA submissions'!$H:$H,'By year'!$A10,'Local HTA submissions'!$C:$C,'By year'!C$5) -> 9 | D10: =COUNTIFS('Local HTA submissions'!$H:$H,'By year'!$A10,'Local HTA submissions'!$C:$C,'By year'!D$5) -> 1 | E10: =COUNTIFS('Local HTA submissions'!$H:$H,'By year'!$A10,'Local HTA submissions'!$C:$C,'By year'!E$5) -> 2 | F10: =COUNTIFS('Local HTA submissions'!$H:$H,'By year'!$A10,'Local HTA submissions'!$C:$C,'By year'!F$5) -> 7 | G10: =COUNTIFS('Local HTA submissions'!$H:$H,'By year'!$A10,'Local HTA submissions'!$C:$C,'By year'!G$5) -> 0 | H10: =COUNTIFS('Local HTA submissions'!$H:$H,'By year'!$A10,'Local HTA submissions'!$C:$C,'By year'!H$5) -> 0 | I10: 5 | J10: 36 | K10: =SUM(B10:J10) -> 65
A11: ='Local HTA submissions'!AG7 -> 2016 | B11: =COUNTIFS('Local HTA submissions'!$H:$H,'By year'!$A11,'Local HTA submissions'!$C:$C,'By year'!B$5) -> 3 | C11: =COUNTIFS('Local HTA submissions'!$H:$H,'By year'!$A11,'Local HTA submissions'!$C:$C,'By year'!C$5) -> 1 | D11: =COUNTIFS('Local HTA submissions'!$H:$H,'By year'!$A11,'Local HTA submissions'!$C:$C,'By year'!D$5) -> 1 | E11: =COUNTIFS('Local HTA submissions'!$H:$H,'By year'!$A11,'Local HTA submissions'!$C:$C,'By year'!E$5) -> 2 | F11: =COUNTIFS('Local HTA submissions'!$H:$H,'By year'!$A11,'Local HTA submissions'!$C:$C,'By year'!F$5) -> 9 | G11: =COUNTIFS('Local HTA submissions'!$H:$H,'By year'!$A11,'Local HTA submissions'!$C:$C,'By year'!G$5) -> 0 | H11: =COUNTIFS('Local HTA submissions'!$H:$H,'By year'!$A11,'Local HTA submissions'!$C:$C,'By year'!H$5) -> 0 | I11: 9 | J11: 31 | K11: =SUM(B11:J11) -> 56
A12: ='Local HTA submissions'!AG6 -> 2017 | B12: =COUNTIFS('Local HTA submissions'!$H:$H,'By year'!$A12,'Local HTA submissions'!$C:$C,'By year'!B$5) -> 5 | C12: =COUNTIFS('Local HTA submissions'!$H:$H,'By year'!$A12,'Local HTA submissions'!$C:$C,'By year'!C$5) -> 1 | D12: =COUNTIFS('Local HTA submissions'!$H:$H,'By year'!$A12,'Local HTA submissions'!$C:$C,'By year'!D$5) -> 0 | E12: =COUNTIFS('Local HTA submissions'!$H:$H,'By year'!$A12,'Local HTA submissions'!$C:$C,'By year'!E$5) -> 2 | F12: =COUNTIFS('Local HTA submissions'!$H:$H,'By year'!$A12,'Local HTA submissions'!$C:$C,'By year'!F$5) -> 11 | G12: =COUNTIFS('Local HTA submissions'!$H:$H,'By year'!$A12,'Local HTA submissions'!$C:$C,'By year'!G$5) -> 0 | H12: =COUNTIFS('Local HTA submissions'!$H:$H,'By year'!$A12,'Local HTA submissions'!$C:$C,'By year'!H$5) -> 0 | I12: 6 | J12: 22 | K12: =SUM(B12:J12) -> 47
A13: ='Local HTA submissions'!AG5 -> 2018 | B13: =COUNTIFS('Local HTA submissions'!$H:$H,'By year'!$A13,'Local HTA submissions'!$C:$C,'By year'!B$5) -> 4 | C13: =COUNTIFS('Local HTA submissions'!$H:$H,'By year'!$A13,'Local HTA submissions'!$C:$C,'By year'!C$5) -> 2 | D13: =COUNTIFS('Local HTA submissions'!$H:$H,'By year'!$A13,'Local HTA submissions'!$C:$C,'By year'!D$5) -> 2 | E13: =COUNTIFS('Local HTA submissions'!$H:$H,'By year'!$A13,'Local HTA submissions'!$C:$C,'By year'!E$5) -> 2 | F13: =COUNTIFS('Local HTA submissions'!$H:$H,'By year'!$A13,'Local HTA submissions'!$C:$C,'By year'!F$5) -> 12 | G13: =COUNTIFS('Local HTA submissions'!$H:$H,'By year'!$A13,'Local HTA submissions'!$C:$C,'By year'!G$5) -> 6 | H13: =COUNTIFS('Local HTA submissions'!$H:$H,'By year'!$A13,'Local HTA submissions'!$C:$C,'By year'!H$5) -> 0 | I13: 7 | J13: 24 | K13: =SUM(B13:J13) -> 59
A14: ='Local HTA submissions'!AG4 -> 2019 | B14: =COUNTIFS('Local HTA submissions'!$H:$H,'By year'!$A14,'Local HTA submissions'!$C:$C,'By year'!B$5) -> 9 | C14: =COUNTIFS('Local HTA submissions'!$H:$H,'By year'!$A14,'Local HTA submissions'!$C:$C,'By year'!C$5) -> 3 | D14: =COUNTIFS('Local HTA submissions'!$H:$H,'By year'!$A14,'Local HTA submissions'!$C:$C,'By year'!D$5) -> 1 | E14: =COUNTIFS('Local HTA submissions'!$H:$H,'By year'!$A14,'Local HTA submissions'!$C:$C,'By year'!E$5) -> 3 | F14: =COUNTIFS('Local HTA submissions'!$H:$H,'By year'!$A14,'Local HTA submissions'!$C:$C,'By year'!F$5) -> 14 | G14: =COUNTIFS('Local HTA submissions'!$H:$H,'By year'!$A14,'Local HTA submissions'!$C:$C,'By year'!G$5) -> 6 | H14: =COUNTIFS('Local HTA submissions'!$H:$H,'By year'!$A14,'Local HTA submissions'!$C:$C,'By year'!H$5) -> 0 | I14: 19 | J14: 22 | K14: =SUM(B14:J14) -> 77
A15: ='Local HTA submissions'!AG3 -> 2020 | B15: =COUNTIFS('Local HTA submissions'!$H:$H,'By year'!$A15,'Local HTA submissions'!$C:$C,'By year'!B$5) -> 5 | C15: =COUNTIFS('Local HTA submissions'!$H:$H,'By year'!$A15,'Local HTA submissions'!$C:$C,'By year'!C$5) -> 3 | D15: =COUNTIFS('Local HTA submissions'!$H:$H,'By year'!$A15,'Local HTA submissions'!$C:$C,'By year'!D$5) -> 0 | E15: =COUNTIFS('Local HTA submissions'!$H:$H,'By year'!$A15,'Local HTA submissions'!$C:$C,'By year'!E$5) -> 2 | F15: =COUNTIFS('Local HTA submissions'!$H:$H,'By year'!$A15,'Local HTA submissions'!$C:$C,'By year'!F$5) -> 25 | G15: =COUNTIFS('Local HTA submissions'!$H:$H,'By year'!$A15,'Local HTA submissions'!$C:$C,'By year'!G$5) -> 17 | H15: =COUNTIFS('Local HTA submissions'!$H:$H,'By year'!$A15,'Local HTA submissions'!$C:$C,'By year'!H$5) -> 0 | I15: 19 | J15: 22 | K15: =SUM(B15:J15) -> 93
A16: ='Local HTA submissions'!AG2 -> 2021 | B16: =COUNTIFS('Local HTA submissions'!$H:$H,'By year'!$A16,'Local HTA submissions'!$C:$C,'By year'!B$5) -> 7 | C16: =COUNTIFS('Local HTA submissions'!$H:$H,'By year'!$A16,'Local HTA submissions'!$C:$C,'By year'!C$5) -> 5 | D16: =COUNTIFS('Local HTA submissions'!$H:$H,'By year'!$A16,'Local HTA submissions'!$C:$C,'By year'!D$5) -> 0 | E16: =COUNTIFS('Local HTA submissions'!$H:$H,'By year'!$A16,'Local HTA submissions'!$C:$C,'By year'!E$5) -> 4 | F16: =COUNTIFS('Local HTA submissions'!$H:$H,'By year'!$A16,'Local HTA submissions'!$C:$C,'By year'!F$5) -> 7 | G16: =COUNTIFS('Local HTA submissions'!$H:$H,'By year'!$A16,'Local HTA submissions'!$C:$C,'By year'!G$5) -> 17 | H16: =COUNTIFS('Local HTA submissions'!$H:$H,'By year'!$A16,'Local HTA submissions'!$C:$C,'By year'!H$5) -> 0 | I16: 4 | J16: 4 | K16: =SUM(B16:J16) -> 48
A17: ='Local HTA submissions'!AG13 -> Ongoing | B17: =COUNTIFS('Local HTA submissions'!$H:$H,'By year'!$A17,'Local HTA submissions'!$C:$C,'By year'!B$5) -> 0 | C17: =COUNTIFS('Local HTA submissions'!$H:$H,'By year'!$A17,'Local HTA submissions'!$C:$C,'By year'!C$5) -> 0 | D17: =COUNTIFS('Local HTA submissions'!$H:$H,'By year'!$A17,'Local HTA submissions'!$C:$C,'By year'!D$5) -> 0 | E17: =COUNTIFS('Local HTA submissions'!$H:$H,'By year'!$A17,'Local HTA submissions'!$C:$C,'By year'!E$5) -> 0 | F17: =COUNTIFS('Local HTA submissions'!$H:$H,'By year'!$A17,'Local HTA submissions'!$C:$C,'By year'!F$5) -> 0 | G17: =COUNTIFS('Local HTA submissions'!$H:$H,'By year'!$A17,'Local HTA submissions'!$C:$C,'By year'!G$5) -> 0 | H17: =COUNTIFS('Local HTA submissions'!$H:$H,'By year'!$A17,'Local HTA submissions'!$C:$C,'By year'!H$5) -> 0 | I17: 4 | J17: 4 | K17: =SUM(B17:J17) -> 8
A18: Total | B18: =SUM(B6:B17) -> 50 | C18: =SUM(C6:C17) -> 27 | D18: =SUM(D6:D17) -> 6 | E18: =SUM(E6:E17) -> 22 | F18: =SUM(F6:F17) -> 85 | G18: =SUM(G6:G17) -> 46 | H18: =SUM(H6:H17) -> 0 | I18: =SUM(I6:I17) -> 73 | J18: =SUM(J6:J17) -> 165 | K18: =SUM(B18:J18) -> 474
A46: HTA submissions by Year & Country
A47: Country | B47: 2012 | C47: 2013 | D47: 2014 | E47: 2015 | F47: 2016 | G47: 2017 | H47: 2018 | I47: 2019 | J47: 2020 | K47: 2021 | L47: Total
A48: ='Local HTA submissions'!AA2 -> England | B48: =COUNTIFS('Local HTA submissions'!$B:$B,'By year'!$A48,'Local HTA submissions'!$H:$H,'By year'!B$47) -> 4 | C48: =COUNTIFS('Local HTA submissions'!$B:$B,'By year'!$A48,'Local HTA submissions'!$H:$H,'By year'!C$47) -> 5 | D48: =COUNTIFS('Local HTA submissions'!$B:$B,'By year'!$A48,'Local HTA submissions'!$H:$H,'By year'!D$47) -> 3 | E48: =COUNTIFS('Local HTA submissions'!$B:$B,'By year'!$A48,'Local HTA submissions'!$H:$H,'By year'!E$47) -> 5 | F48: =COUNTIFS('Local HTA submissions'!$B:$B,'By year'!$A48,'Local HTA submissions'!$H:$H,'By year'!F$47) -> 3 | G48: =COUNTIFS('Local HTA submissions'!$B:$B,'By year'!$A48,'Local HTA submissions'!$H:$H,'By year'!G$47) -> 5 | H48: =COUNTIFS('Local HTA submissions'!$B:$B,'By year'!$A48,'Local HTA submissions'!$H:$H,'By year'!H$47) -> 4 | I48: =COUNTIFS('Local HTA submissions'!$B:$B,'By year'!$A48,'Local HTA submissions'!$H:$H,'By year'!I$47) -> 9 | ... K48: =COUNTIFS('Local HTA submissions'!$B:$B,'By year'!$A48,'Local HTA submissions'!$H:$H,'By year'!K$47) -> 7 | L48: =SUM(B48:K48) -> 50
A49: ='Local HTA submissions'!AA3 -> Scotland | B49: =COUNTIFS('Local HTA submissions'!$B:$B,'By year'!$A49,'Local HTA submissions'!$H:$H,'By year'!B$47) -> 2 | C49: =COUNTIFS('Local HTA submissions'!$B:$B,'By year'!$A49,'Local HTA submissions'!$H:$H,'By year'!C$47) -> 1 | D49: =COUNTIFS('Local HTA submissions'!$B:$B,'By year'!$A49,'Local HTA submissions'!$H:$H,'By year'!D$47) -> 0 | E49: =COUNTIFS('Local HTA submissions'!$B:$B,'By year'!$A49,'Local HTA submissions'!$H:$H,'By year'!E$47) -> 9 | F49: =COUNTIFS('Local HTA submissions'!$B:$B,'By year'!$A49,'Local HTA submissions'!$H:$H,'By year'!F$47) -> 1 | G49: =COUNTIFS('Local HTA submissions'!$B:$B,'By year'!$A49,'Local HTA submissions'!$H:$H,'By year'!G$47) -> 1 | H49: =COUNTIFS('Local HTA submissions'!$B:$B,'By year'!$A49,'Local HTA submissions'!$H:$H,'By year'!H$47) -> 2 | I49: =COUNTIFS('Local HTA submissions'!$B:$B,'By year'!$A49,'Local HTA submissions'!$H:$H,'By year'!I$47) -> 3 | ... K49: =COUNTIFS('Local HTA submissions'!$B:$B,'By year'!$A49,'Local HTA submissions'!$H:$H,'By year'!K$47) -> 5 | L49: =SUM(B49:K49) -> 27
A50: ='Local HTA submissions'!AA4 -> Wales | B50: =COUNTIFS('Local HTA submissions'!$B:$B,'By year'!$A50,'Local HTA submissions'!$H:$H,'By year'!B$47) -> 0 | C50: =COUNTIFS('Local HTA submissions'!$B:$B,'By year'!$A50,'Local HTA submissions'!$H:$H,'By year'!C$47) -> 1 | D50: =COUNTIFS('Local HTA submissions'!$B:$B,'By year'!$A50,'Local HTA submissions'!$H:$H,'By year'!D$47) -> 0 | E50: =COUNTIFS('Local HTA submissions'!$B:$B,'By year'!$A50,'Local HTA submissions'!$H:$H,'By year'!E$47) -> 1 | F50: =COUNTIFS('Local HTA submissions'!$B:$B,'By year'!$A50,'Local HTA submissions'!$H:$H,'By year'!F$47) -> 1 | G50: =COUNTIFS('Local HTA submissions'!$B:$B,'By year'!$A50,'Local HTA submissions'!$H:$H,'By year'!G$47) -> 0 | H50: =COUNTIFS('Local HTA submissions'!$B:$B,'By year'!$A50,'Local HTA submissions'!$H:$H,'By year'!H$47) -> 2 | I50: =COUNTIFS('Local HTA submissions'!$B:$B,'By year'!$A50,'Local HTA submissions'!$H:$H,'By year'!I$47) -> 1 | ... K50: =COUNTIFS('Local HTA submissions'!$B:$B,'By year'!$A50,'Local HTA submissions'!$H:$H,'By year'!K$47) -> 0 | L50: =SUM(B50:K50) -> 6
A51: ='Local HTA submissions'!AA5 -> Ireland | B51: =COUNTIFS('Local HTA submissions'!$B:$B,'By year'!$A51,'Local HTA submissions'!$H:$H,'By year'!B$47) -> 0 | C51: =COUNTIFS('Local HTA submissions'!$B:$B,'By year'!$A51,'Local HTA submissions'!$H:$H,'By year'!C$47) -> 3 | D51: =COUNTIFS('Local HTA submissions'!$B:$B,'By year'!$A51,'Local HTA submissions'!$H:$H,'By year'!D$47) -> 2 | E51: =COUNTIFS('Local HTA submissions'!$B:$B,'By year'!$A51,'Local HTA submissions'!$H:$H,'By year'!E$47) -> 2 | F51: =COUNTIFS('Local HTA submissions'!$B:$B,'By year'!$A51,'Local HTA submissions'!$H:$H,'By year'!F$47) -> 2 | G51: =COUNTIFS('Local HTA submissions'!$B:$B,'By year'!$A51,'Local HTA submissions'!$H:$H,'By year'!G$47) -> 2 | H51: =COUNTIFS('Local HTA submissions'!$B:$B,'By year'!$A51,'Local HTA submissions'!$H:$H,'By year'!H$47) -> 2 | I51: =COUNTIFS('Local HTA submissions'!$B:$B,'By year'!$A51,'Local HTA submissions'!$H:$H,'By year'!I$47) -> 3 | ... K51: =COUNTIFS('Local HTA submissions'!$B:$B,'By year'!$A51,'Local HTA submissions'!$H:$H,'By year'!K$47) -> 4 | L51: =SUM(B51:K51) -> 22
A52: ='Local HTA submissions'!AA6 -> Germany | B52: =COUNTIFS('Local HTA submissions'!$B:$B,'By year'!$A52,'Local HTA submissions'!$H:$H,'By year'!B$47) -> 0 | C52: =COUNTIFS('Local HTA submissions'!$B:$B,'By year'!$A52,'Local HTA submissions'!$H:$H,'By year'!C$47) -> 0 | D52: =COUNTIFS('Local HTA submissions'!$B:$B,'By year'!$A52,'Local HTA submissions'!$H:$H,'By year'!D$47) -> 0 | E52: =COUNTIFS('Local HTA submissions'!$B:$B,'By year'!$A52,'Local HTA submissions'!$H:$H,'By year'!E$47) -> 7 | F52: =COUNTIFS('Local HTA submissions'!$B:$B,'By year'!$A52,'Local HTA submissions'!$H:$H,'By year'!F$47) -> 9 | G52: =COUNTIFS('Local HTA submissions'!$B:$B,'By year'!$A52,'Local HTA submissions'!$H:$H,'By year'!G$47) -> 11 | H52: =COUNTIFS('Local HTA submissions'!$B:$B,'By year'!$A52,'Local HTA submissions'!$H:$H,'By year'!H$47) -> 12 | I52: =COUNTIFS('Local HTA submissions'!$B:$B,'By year'!$A52,'Local HTA submissions'!$H:$H,'By year'!I$47) -> 14 | ... K52: =COUNTIFS('Local HTA submissions'!$B:$B,'By year'!$A52,'Local HTA submissions'!$H:$H,'By year'!K$47) -> 7 | L52: =SUM(B52:K52) -> 85
A53: ='Local HTA submissions'!AA7 -> Spain | B53: =COUNTIFS('Local HTA submissions'!$B:$B,'By year'!$A53,'Local HTA submissions'!$H:$H,'By year'!B$47) -> 0 | C53: =COUNTIFS('Local HTA submissions'!$B:$B,'By year'!$A53,'Local HTA submissions'!$H:$H,'By year'!C$47) -> 0 | D53: =COUNTIFS('Local HTA submissions'!$B:$B,'By year'!$A53,'Local HTA submissions'!$H:$H,'By year'!D$47) -> 0 | E53: =COUNTIFS('Local HTA submissions'!$B:$B,'By year'!$A53,'Local HTA submissions'!$H:$H,'By year'!E$47) -> 5 | F53: =COUNTIFS('Local HTA submissions'!$B:$B,'By year'!$A53,'Local HTA submissions'!$H:$H,'By year'!F$47) -> 8 | G53: =COUNTIFS('Local HTA submissions'!$B:$B,'By year'!$A53,'Local HTA submissions'!$H:$H,'By year'!G$47) -> 6 | H53: =COUNTIFS('Local HTA submissions'!$B:$B,'By year'!$A53,'Local HTA submissions'!$H:$H,'By year'!H$47) -> 7 | I53: =COUNTIFS('Local HTA submissions'!$B:$B,'By year'!$A53,'Local HTA submissions'!$H:$H,'By year'!I$47) -> 7 | ... K53: =COUNTIFS('Local HTA submissions'!$B:$B,'By year'!$A53,'Local HTA submissions'!$H:$H,'By year'!K$47) -> 2 | L53: =SUM(B53:K53) -> 40
A54: ='Local HTA submissions'!AA8 -> Italy | B54: =COUNTIFS('Local HTA submissions'!$B:$B,'By year'!$A54,'Local HTA submissions'!$H:$H,'By year'!B$47) -> 0 | C54: =COUNTIFS('Local HTA submissions'!$B:$B,'By year'!$A54,'Local HTA submissions'!$H:$H,'By year'!C$47) -> 0 | D54: =COUNTIFS('Local HTA submissions'!$B:$B,'By year'!$A54,'Local HTA submissions'!$H:$H,'By year'!D$47) -> 0 | E54: =COUNTIFS('Local HTA submissions'!$B:$B,'By year'!$A54,'Local HTA submissions'!$H:$H,'By year'!E$47) -> 0 | F54: =COUNTIFS('Local HTA submissions'!$B:$B,'By year'!$A54,'Local HTA submissions'!$H:$H,'By year'!F$47) -> 0 | G54: =COUNTIFS('Local HTA submissions'!$B:$B,'By year'!$A54,'Local HTA submissions'!$H:$H,'By year'!G$47) -> 0 | H54: =COUNTIFS('Local HTA submissions'!$B:$B,'By year'!$A54,'Local HTA submissions'!$H:$H,'By year'!H$47) -> 6 | I54: =COUNTIFS('Local HTA submissions'!$B:$B,'By year'!$A54,'Local HTA submissions'!$H:$H,'By year'!I$47) -> 6 | ... K54: =COUNTIFS('Local HTA submissions'!$B:$B,'By year'!$A54,'Local HTA submissions'!$H:$H,'By year'!K$47) -> 17 | L54: =SUM(B54:K54) -> 46
A55: ='Local HTA submissions'!AA9 -> France | B55: =COUNTIFS('Local HTA submissions'!$B:$B,'By year'!$A55,'Local HTA submissions'!$H:$H,'By year'!B$47) -> 0 | C55: =COUNTIFS('Local HTA submissions'!$B:$B,'By year'!$A55,'Local HTA submissions'!$H:$H,'By year'!C$47) -> 0 | D55: =COUNTIFS('Local HTA submissions'!$B:$B,'By year'!$A55,'Local HTA submissions'!$H:$H,'By year'!D$47) -> 0 | E55: 41 | F55: 40 | G55: 28 | H55: 31 | I55: 41 | J55: 41 | K55: 8 | L55: =SUM(B55:K55) -> 230
A56: ='Local HTA submissions'!AA10 -> Portugal | B56: =COUNTIFS('Local HTA submissions'!$B:$B,'By year'!$A56,'Local HTA submissions'!$H:$H,'By year'!B$47) -> 0 | C56: =COUNTIFS('Local HTA submissions'!$B:$B,'By year'!$A56,'Local HTA submissions'!$H:$H,'By year'!C$47) -> 0 | D56: =COUNTIFS('Local HTA submissions'!$B:$B,'By year'!$A56,'Local HTA submissions'!$H:$H,'By year'!D$47) -> 0 | E56: =COUNTIFS('Local HTA submissions'!$B:$B,'By year'!$A56,'Local HTA submissions'!$H:$H,'By year'!E$47) -> 0 | F56: =COUNTIFS('Local HTA submissions'!$B:$B,'By year'!$A56,'Local HTA submissions'!$H:$H,'By year'!F$47) -> 0 | G56: =COUNTIFS('Local HTA submissions'!$B:$B,'By year'!$A56,'Local HTA submissions'!$H:$H,'By year'!G$47) -> 0 | H56: =COUNTIFS('Local HTA submissions'!$B:$B,'By year'!$A56,'Local HTA submissions'!$H:$H,'By year'!H$47) -> 0 | I56: =COUNTIFS('Local HTA submissions'!$B:$B,'By year'!$A56,'Local HTA submissions'!$H:$H,'By year'!I$47) -> 0 | ... K56: =COUNTIFS('Local HTA submissions'!$B:$B,'By year'!$A56,'Local HTA submissions'!$H:$H,'By year'!K$47) -> 4 | L56: =SUM(B56:K56) -> 6
A57: ='Local HTA submissions'!AA11 -> Greece | B57: =COUNTIFS('Local HTA submissions'!$B:$B,'By year'!$A57,'Local HTA submissions'!$H:$H,'By year'!B$47) -> 0 | C57: =COUNTIFS('Local HTA submissions'!$B:$B,'By year'!$A57,'Local HTA submissions'!$H:$H,'By year'!C$47) -> 0 | D57: =COUNTIFS('Local HTA submissions'!$B:$B,'By year'!$A57,'Local HTA submissions'!$H:$H,'By year'!D$47) -> 0 | E57: =COUNTIFS('Local HTA submissions'!$B:$B,'By year'!$A57,'Local HTA submissions'!$H:$H,'By year'!E$47) -> 0 | F57: =COUNTIFS('Local HTA submissions'!$B:$B,'By year'!$A57,'Local HTA submissions'!$H:$H,'By year'!F$47) -> 0 | G57: =COUNTIFS('Local HTA submissions'!$B:$B,'By year'!$A57,'Local HTA submissions'!$H:$H,'By year'!G$47) -> 0 | H57: =COUNTIFS('Local HTA submissions'!$B:$B,'By year'!$A57,'Local HTA submissions'!$H:$H,'By year'!H$47) -> 1 | I57: =COUNTIFS('Local HTA submissions'!$B:$B,'By year'!$A57,'Local HTA submissions'!$H:$H,'By year'!I$47) -> 4 | ... K57: =COUNTIFS('Local HTA submissions'!$B:$B,'By year'!$A57,'Local HTA submissions'!$H:$H,'By year'!K$47) -> 6 | L57: =SUM(B57:K57) -> 20
A58: ='Local HTA submissions'!AA12 -> Netherlands | B58: =COUNTIFS('Local HTA submissions'!$B:$B,'By year'!$A58,'Local HTA submissions'!$H:$H,'By year'!B$47) -> 0 | C58: =COUNTIFS('Local HTA submissions'!$B:$B,'By year'!$A58,'Local HTA submissions'!$H:$H,'By year'!C$47) -> 0 | D58: =COUNTIFS('Local HTA submissions'!$B:$B,'By year'!$A58,'Local HTA submissions'!$H:$H,'By year'!D$47) -> 0 | E58: =COUNTIFS('Local HTA submissions'!$B:$B,'By year'!$A58,'Local HTA submissions'!$H:$H,'By year'!E$47) -> 0 | F58: =COUNTIFS('Local HTA submissions'!$B:$B,'By year'!$A58,'Local HTA submissions'!$H:$H,'By year'!F$47) -> 0 | G58: =COUNTIFS('Local HTA submissions'!$B:$B,'By year'!$A58,'Local HTA submissions'!$H:$H,'By year'!G$47) -> 0 | H58: =COUNTIFS('Local HTA submissions'!$B:$B,'By year'!$A58,'Local HTA submissions'!$H:$H,'By year'!H$47) -> 0 | I58: =COUNTIFS('Local HTA submissions'!$B:$B,'By year'!$A58,'Local HTA submissions'!$H:$H,'By year'!I$47) -> 2 | ... K58: =COUNTIFS('Local HTA submissions'!$B:$B,'By year'!$A58,'Local HTA submissions'!$H:$H,'By year'!K$47) -> 3 | L58: =SUM(B58:K58) -> 10
A59: ='Local HTA submissions'!AA13 -> Czech Republic | B59: =COUNTIFS('Local HTA submissions'!$B:$B,'By year'!$A59,'Local HTA submissions'!$H:$H,'By year'!B$47) -> 0 | C59: =COUNTIFS('Local HTA submissions'!$B:$B,'By year'!$A59,'Local HTA submissions'!$H:$H,'By year'!C$47) -> 0 | D59: =COUNTIFS('Local HTA submissions'!$B:$B,'By year'!$A59,'Local HTA submissions'!$H:$H,'By year'!D$47) -> 0 | E59: =COUNTIFS('Local HTA submissions'!$B:$B,'By year'!$A59,'Local HTA submissions'!$H:$H,'By year'!E$47) -> 0 | F59: =COUNTIFS('Local HTA submissions'!$B:$B,'By year'!$A59,'Local HTA submissions'!$H:$H,'By year'!F$47) -> 0 | G59: =COUNTIFS('Local HTA submissions'!$B:$B,'By year'!$A59,'Local HTA submissions'!$H:$H,'By year'!G$47) -> 0 | H59: =COUNTIFS('Local HTA submissions'!$B:$B,'By year'!$A59,'Local HTA submissions'!$H:$H,'By year'!H$47) -> 1 | I59: =COUNTIFS('Local HTA submissions'!$B:$B,'By year'!$A59,'Local HTA submissions'!$H:$H,'By year'!I$47) -> 0 | ... K59: =COUNTIFS('Local HTA submissions'!$B:$B,'By year'!$A59,'Local HTA submissions'!$H:$H,'By year'!K$47) -> 0 | L59: =SUM(B59:K59) -> 1
A60: ='Local HTA submissions'!AA14 -> Slovakia | B60: =COUNTIFS('Local HTA submissions'!$B:$B,'By year'!$A60,'Local HTA submissions'!$H:$H,'By year'!B$47) -> 0 | C60: =COUNTIFS('Local HTA submissions'!$B:$B,'By year'!$A60,'Local HTA submissions'!$H:$H,'By year'!C$47) -> 0 | D60: =COUNTIFS('Local HTA submissions'!$B:$B,'By year'!$A60,'Local HTA submissions'!$H:$H,'By year'!D$47) -> 0 | E60: =COUNTIFS('Local HTA submissions'!$B:$B,'By year'!$A60,'Local HTA submissions'!$H:$H,'By year'!E$47) -> 0 | F60: =COUNTIFS('Local HTA submissions'!$B:$B,'By year'!$A60,'Local HTA submissions'!$H:$H,'By year'!F$47) -> 0 | G60: =COUNTIFS('Local HTA submissions'!$B:$B,'By year'!$A60,'Local HTA submissions'!$H:$H,'By year'!G$47) -> 0 | H60: =COUNTIFS('Local HTA submissions'!$B:$B,'By year'!$A60,'Local HTA submissions'!$H:$H,'By year'!H$47) -> 1 | I60: =COUNTIFS('Local HTA submissions'!$B:$B,'By year'!$A60,'Local HTA submissions'!$H:$H,'By year'!I$47) -> 0 | ... K60: =COUNTIFS('Local HTA submissions'!$B:$B,'By year'!$A60,'Local HTA submissions'!$H:$H,'By year'!K$47) -> 0 | L60: =SUM(B60:K60) -> 1
A61: ='Local HTA submissions'!AA15 -> 0 | B61: =COUNTIFS('Local HTA submissions'!$B:$B,'By year'!$A61,'Local HTA submissions'!$H:$H,'By year'!B$47) -> 0 | C61: =COUNTIFS('Local HTA submissions'!$B:$B,'By year'!$A61,'Local HTA submissions'!$H:$H,'By year'!C$47) -> 0 | D61: =COUNTIFS('Local HTA submissions'!$B:$B,'By year'!$A61,'Local HTA submissions'!$H:$H,'By year'!D$47) -> 0 | E61: =COUNTIFS('Local HTA submissions'!$B:$B,'By year'!$A61,'Local HTA submissions'!$H:$H,'By year'!E$47) -> 0 | F61: =COUNTIFS('Local HTA submissions'!$B:$B,'By year'!$A61,'Local HTA submissions'!$H:$H,'By year'!F$47) -> 0 | G61: =COUNTIFS('Local HTA submissions'!$B:$B,'By year'!$A61,'Local HTA submissions'!$H:$H,'By year'!G$47) -> 0 | H61: =COUNTIFS('Local HTA submissions'!$B:$B,'By year'!$A61,'Local HTA submissions'!$H:$H,'By year'!H$47) -> 0 | I61: =COUNTIFS('Local HTA submissions'!$B:$B,'By year'!$A61,'Local HTA submissions'!$H:$H,'By year'!I$47) -> 0 | ... K61: =COUNTIFS('Local HTA submissions'!$B:$B,'By year'!$A61,'Local HTA submissions'!$H:$H,'By year'!K$47) -> 0 | L61: =SUM(B61:K61) -> 0
A62: ='Local HTA submissions'!AA16 -> 0 | B62: =COUNTIFS('Local HTA submissions'!$B:$B,'By year'!$A62,'Local HTA submissions'!$H:$H,'By year'!B$47) -> 0 | C62: =COUNTIFS('Local HTA submissions'!$B:$B,'By year'!$A62,'Local HTA submissions'!$H:$H,'By year'!C$47) -> 0 | D62: =COUNTIFS('Local HTA submissions'!$B:$B,'By year'!$A62,'Local HTA submissions'!$H:$H,'By year'!D$47) -> 0 | E62: =COUNTIFS('Local HTA submissions'!$B:$B,'By year'!$A62,'Local HTA submissions'!$H:$H,'By year'!E$47) -> 0 | F62: =COUNTIFS('Local HTA submissions'!$B:$B,'By year'!$A62,'Local HTA submissions'!$H:$H,'By year'!F$47) -> 0 | G62: =COUNTIFS('Local HTA submissions'!$B:$B,'By year'!$A62,'Local HTA submissions'!$H:$H,'By year'!G$47) -> 0 | H62: =COUNTIFS('Local HTA submissions'!$B:$B,'By year'!$A62,'Local HTA submissions'!$H:$H,'By year'!H$47) -> 0 | I62: =COUNTIFS('Local HTA submissions'!$B:$B,'By year'!$A62,'Local HTA submissions'!$H:$H,'By year'!I$47) -> 0 | ... K62: =COUNTIFS('Local HTA submissions'!$B:$B,'By year'!$A62,'Local HTA submissions'!$H:$H,'By year'!K$47) -> 0 | L62: =SUM(B62:K62) -> 0
A63: ='Local HTA submissions'!AA17 -> 0 | B63: =COUNTIFS('Local HTA submissions'!$B:$B,'By year'!$A63,'Local HTA submissions'!$H:$H,'By year'!B$47) -> 0 | C63: =COUNTIFS('Local HTA submissions'!$B:$B,'By year'!$A63,'Local HTA submissions'!$H:$H,'By year'!C$47) -> 0 | D63: =COUNTIFS('Local HTA submissions'!$B:$B,'By year'!$A63,'Local HTA submissions'!$H:$H,'By year'!D$47) -> 0 | E63: =COUNTIFS('Local HTA submissions'!$B:$B,'By year'!$A63,'Local HTA submissions'!$H:$H,'By year'!E$47) -> 0 | F63: =COUNTIFS('Local HTA submissions'!$B:$B,'By year'!$A63,'Local HTA submissions'!$H:$H,'By year'!F$47) -> 0 | G63: =COUNTIFS('Local HTA submissions'!$B:$B,'By year'!$A63,'Local HTA submissions'!$H:$H,'By year'!G$47) -> 0 | H63: =COUNTIFS('Local HTA submissions'!$B:$B,'By year'!$A63,'Local HTA submissions'!$H:$H,'By year'!H$47) -> 0 | I63: =COUNTIFS('Local HTA submissions'!$B:$B,'By year'!$A63,'Local HTA submissions'!$H:$H,'By year'!I$47) -> 0 | ... K63: =COUNTIFS('Local HTA submissions'!$B:$B,'By year'!$A63,'Local HTA submissions'!$H:$H,'By year'!K$47) -> 0 | L63: =SUM(B63:K63) -> 0
A64: ='Local HTA submissions'!AA18 -> 0 | B64: =COUNTIFS('Local HTA submissions'!$B:$B,'By year'!$A64,'Local HTA submissions'!$H:$H,'By year'!B$47) -> 0 | C64: =COUNTIFS('Local HTA submissions'!$B:$B,'By year'!$A64,'Local HTA submissions'!$H:$H,'By year'!C$47) -> 0 | D64: =COUNTIFS('Local HTA submissions'!$B:$B,'By year'!$A64,'Local HTA submissions'!$H:$H,'By year'!D$47) -> 0 | E64: =COUNTIFS('Local HTA submissions'!$B:$B,'By year'!$A64,'Local HTA submissions'!$H:$H,'By year'!E$47) -> 0 | F64: =COUNTIFS('Local HTA submissions'!$B:$B,'By year'!$A64,'Local HTA submissions'!$H:$H,'By year'!F$47) -> 0 | G64: =COUNTIFS('Local HTA submissions'!$B:$B,'By year'!$A64,'Local HTA submissions'!$H:$H,'By year'!G$47) -> 0 | H64: =COUNTIFS('Local HTA submissions'!$B:$B,'By year'!$A64,'Local HTA submissions'!$H:$H,'By year'!H$47) -> 0 | I64: =COUNTIFS('Local HTA submissions'!$B:$B,'By year'!$A64,'Local HTA submissions'!$H:$H,'By year'!I$47) -> 0 | ... K64: =COUNTIFS('Local HTA submissions'!$B:$B,'By year'!$A64,'Local HTA submissions'!$H:$H,'By year'!K$47) -> 0 | L64: =SUM(B64:K64) -> 0
A65: ='Local HTA submissions'!AA19 -> 0 | B65: =COUNTIFS('Local HTA submissions'!$B:$B,'By year'!$A65,'Local HTA submissions'!$H:$H,'By year'!B$47) -> 0 | C65: =COUNTIFS('Local HTA submissions'!$B:$B,'By year'!$A65,'Local HTA submissions'!$H:$H,'By year'!C$47) -> 0 | D65: =COUNTIFS('Local HTA submissions'!$B:$B,'By year'!$A65,'Local HTA submissions'!$H:$H,'By year'!D$47) -> 0 | E65: =COUNTIFS('Local HTA submissions'!$B:$B,'By year'!$A65,'Local HTA submissions'!$H:$H,'By year'!E$47) -> 0 | F65: =COUNTIFS('Local HTA submissions'!$B:$B,'By year'!$A65,'Local HTA submissions'!$H:$H,'By year'!F$47) -> 0 | G65: =COUNTIFS('Local HTA submissions'!$B:$B,'By year'!$A65,'Local HTA submissions'!$H:$H,'By year'!G$47) -> 0 | H65: =COUNTIFS('Local HTA submissions'!$B:$B,'By year'!$A65,'Local HTA submissions'!$H:$H,'By year'!H$47) -> 0 | I65: =COUNTIFS('Local HTA submissions'!$B:$B,'By year'!$A65,'Local HTA submissions'!$H:$H,'By year'!I$47) -> 0 | ... K65: =COUNTIFS('Local HTA submissions'!$B:$B,'By year'!$A65,'Local HTA submissions'!$H:$H,'By year'!K$47) -> 0 | L65: =SUM(B65:K65) -> 0
A66: All countries | B66: =COUNTIFS('Local HTA submissions'!$B:$B,'By year'!$A66,'Local HTA submissions'!$H:$H,'By year'!B$47) -> 0 | C66: =SUBTOTAL(109,C48:C65) -> 10 | D66: =SUBTOTAL(109,D48:D65) -> 5 | E66: =SUBTOTAL(109,E48:E65) -> 70 | F66: =SUBTOTAL(109,F48:F65) -> 64 | G66: =SUBTOTAL(109,G48:G65) -> 53 | H66: =SUBTOTAL(109,H48:H65) -> 69 | I66: =SUBTOTAL(109,I48:I65) -> 90 | J66: =SUBTOTAL(109,J48:J65) -> 114 | K66: =SUBTOTAL(109,K48:K65) -> 63 | L66: =SUM(B66:K66) -> 538
A89: HTA scientific advice
A91: HTA scientific advices by Year & HTA body
A92: Year | B92: CADTH | C92: EUnetHTA | D92: G-BA | E92: HAS | F92: NICE | G92: Parallel EMA / HTA | H92: ZIN | I92: Total
...

Sheet By therapy area
A1: Local HTA submissions
